<?xml version="1.0" encoding="utf-8"?>
<!-- This URDF was automatically created by SolidWorks to URDF Exporter! Originally created by
Stephen Brawner (brawner@gmail.com) 
     Commit Version: 1.5.1-0-g916b5db  Build Version: 1.5.7152.31018
     For more information, please see http://wiki.ros.org/sw_urdf_exporter -->
<robot
  name="BamBoBot_urdf">
  <link
    name="base_footprint">

    <inertial>
      <origin
        xyz="-0.0044537 0.00054543 0.065213"
        rpy="0 0 0" />
      <mass
        value="0.51315" />
      <inertia
        ixx="0.00030965"
        ixy="-4.1668E-07"
        ixz="-9.824E-09"
        iyy="0.0011198"
        iyz="-3.1935E-09"
        izz="0.0013997" />
    </inertial>

    <visual>
      <origin
        xyz="0 0 0"
        rpy="0 0 0" />
      <geometry>
        <mesh
          filename="package://BamBoBot_robot/meshes/base_footprint.STL" />
      </geometry>
      <material
        name="">
        <color
          rgba="0.8 0.8 0.8 1" />
      </material>
    </visual>
    <collision>
      <origin
        xyz="0 0 0"
        rpy="0 0 0" />
      <geometry>
        <mesh
          filename="package://BamBoBot_robot/meshes/base_footprint.STL" />
      </geometry>
    </collision>
  </link>

  <link
    name="Wheel1_link">
    <inertial>
      <origin
        xyz="-4.457E-09 -2.3661E-10 -0.011873"
        rpy="0 0 0" />
      <mass
        value="0.021403" />
      <inertia
        ixx="8.6276E-06"
        ixy="1.9097E-13"
        ixz="-2.5077E-15"
        iyy="8.6271E-06"
        iyz="2.1262E-14"
        izz="1.4513E-05" />
    </inertial>
    <visual>
      <origin
        xyz="0 0 0"
        rpy="0 0 0" />
      <geometry>
        <mesh
          filename="package://BamBoBot_robot/meshes/Wheel1_link.STL" />
      </geometry>
      <material
        name="">
        <color
          rgba="0.79216 0.81961 0.93333 1" />
      </material>
    </visual>
    <collision>
      <origin
        xyz="0 0 0"
        rpy="0 0 0" />
      <geometry>
        <mesh
          filename="package://BamBoBot_robot/meshes/Wheel1_link.STL" />
      </geometry>
    </collision>
  </link>
  <joint
    name="Wheel1_joint"
    type="continuous">
    <origin
      xyz="-0.0845 -0.093 0.03396"
      rpy="1.5708 -0.41487 0" />
    <parent
      link="base_footprint" />
    <child
      link="Wheel1_link" />
    <axis
      xyz="0 0 -1" />
    <limit
      effort="100"
      velocity="100" />
    <dynamics
      damping="0.1"
      friction="0.1" />
  </joint>
  <link
    name="Wheel4_link">
    <inertial>
      <origin
        xyz="-4.47967409000771E-09 -2.00088563773182E-10 -0.0118729796550801"
        rpy="0 0 0" />
      <mass
        value="0.0214028332272462" />
      <inertia
        ixx="8.62757650974969E-06"
        ixy="1.91216291508845E-13"
        ixz="-4.86484019015035E-15"
        iyy="8.62710486607564E-06"
        iyz="1.65263287059379E-14"
        izz="1.45133171586975E-05" />
    </inertial>
    <visual>
      <origin
        xyz="0 0 0"
        rpy="0 0 0" />
      <geometry>
        <mesh
          filename="package://BamBoBot_robot/meshes/Wheel4_link.STL" />
      </geometry>
      <material
        name="">
        <color
          rgba="0.792156862745098 0.819607843137255 0.933333333333333 1" />
      </material>
    </visual>
    <collision>
      <origin
        xyz="0 0 0"
        rpy="0 0 0" />
      <geometry>
        <mesh
          filename="package://BamBoBot_robot/meshes/Wheel4_link.STL" />
      </geometry>
    </collision>
  </link>
  <joint
    name="Wheel4_joint"
    type="continuous">
    <origin
      xyz="0.0845 -0.0914 0.03396"
      rpy="1.5708 -0.43724 0" />
    <parent
      link="base_footprint" />
    <child
      link="Wheel4_link" />
    <axis
      xyz="0 0 -1" />
    <limit
      effort="100"
      velocity="100" />
    <dynamics
      damping="0.1"
      friction="0.1" />
  </joint>
  <link
    name="Wheel3_link">
    <inertial>
      <origin
        xyz="-4.51335598061764E-09 -2.62405278061983E-10 -0.0118729796549858"
        rpy="0 0 0" />
      <mass
        value="0.021402833225506" />
      <inertia
        ixx="8.62757650976568E-06"
        ixy="1.9109224941001E-13"
        ixz="3.63428269949823E-15"
        iyy="8.62710486560369E-06"
        iyz="1.74119520997636E-14"
        izz="1.45133171582482E-05" />
    </inertial>
    <visual>
      <origin
        xyz="0 0 0"
        rpy="0 0 0" />
      <geometry>
        <mesh
          filename="package://BamBoBot_robot/meshes/Wheel3_link.STL" />
      </geometry>
      <material
        name="">
        <color
          rgba="0.792156862745098 0.819607843137255 0.933333333333333 1" />
      </material>
    </visual>
    <collision>
      <origin
        xyz="0 0 0"
        rpy="0 0 0" />
      <geometry>
        <mesh
          filename="package://BamBoBot_robot/meshes/Wheel3_link.STL" />
      </geometry>
    </collision>
  </link>
  <joint
    name="Wheel3_joint"
    type="continuous">
    <origin
      xyz="-0.0845 0.0912 0.03396"
      rpy="-1.5708 0.094735 0" />
    <parent
      link="base_footprint" />
    <child
      link="Wheel3_link" />
    <axis
      xyz="0 0 -1" />
    <limit
      effort="100"
      velocity="100" />
    <dynamics
      damping="0.1"
      friction="0.1" />
  </joint>
  <link
    name="Wheel2_link">
    <inertial>
      <origin
        xyz="-4.53444783804491E-09 -2.48747952791284E-10 -0.0118729796550119"
        rpy="0 0 0" />
      <mass
        value="0.0214028332249902" />
      <inertia
        ixx="8.62757650973741E-06"
        ixy="1.91238453278877E-13"
        ixz="3.53400033359113E-15"
        iyy="8.62710486536401E-06"
        iyz="1.43850105367816E-14"
        izz="1.45133171579871E-05" />
    </inertial>
    <visual>
      <origin
        xyz="0 0 0"
        rpy="0 0 0" />
      <geometry>
        <mesh
          filename="package://BamBoBot_robot/meshes/Wheel2_link.STL" />
      </geometry>
      <material
        name="">
        <color
          rgba="0.792156862745098 0.819607843137255 0.933333333333333 1" />
      </material>
    </visual>
    <collision>
      <origin
        xyz="0 0 0"
        rpy="0 0 0" />
      <geometry>
        <mesh
          filename="package://BamBoBot_robot/meshes/Wheel2_link.STL" />
      </geometry>
    </collision>
  </link>
  <joint
    name="Wheel2_joint"
    type="continuous">
    <origin
      xyz="0.0845 0.0912 0.03396"
      rpy="1.5708 0.96948 -3.1416" />
    <parent
      link="base_footprint" />
    <child
      link="Wheel2_link" />
    <axis
      xyz="0 0 -1" />
    <limit
      effort="100"
      velocity="100" />
    <dynamics
      damping="0.1"
      friction="0.1" />
  </joint>
  <link
    name="lidar_link">
    <inertial>
      <origin
        xyz="0 0 0"
        rpy="0 0 0" />
      <mass
        value="0" />
      <inertia
        ixx="0"
        ixy="0"
        ixz="0"
        iyy="0"
        iyz="0"
        izz="0" />
    </inertial>
    <visual>
      <origin
        xyz="0 0 0"
        rpy="0 0 0" />
      <geometry>
        <mesh
          filename="package://BamBoBot_robot/meshes/lidar_link.STL" />
      </geometry>
      <material
        name="">
        <color
          rgba="1 1 1 1" />
      </material>
    </visual>
    <collision>
      <origin
        xyz="0 0 0"
        rpy="0 0 0" />
      <geometry>
        <mesh
          filename="package://BamBoBot_robot/meshes/lidar_link.STL" />
      </geometry>
    </collision>
  </link>
  <joint
    name="lidar_joint"
    type="revolute">
    <origin
      xyz="0.027171 0.0019102 0.14081"
      rpy="1.5708 0 -0.0062994" />
    <parent
      link="base_footprint" />
    <child
      link="lidar_link" />
    <axis
      xyz="0 -1 0" />
    <limit
      lower="0"
      upper="0"
      effort="0"
      velocity="0" />
  </joint>
</robot>