<?xml version="1.0"?>
<robot xmlns:xacro="http://www.ros.org/wiki/xacro">

    <xacro:include filename="inertial_macros.xacro" />

    <material name="white">
        <color rgba="1 1 1 1" />
    </material>

    <material name="orange">
        <color rgba="1 0.3 0.1 1" />
    </material>

    <material name="blue">
        <color rgba="0.2 0.2 1 1" />
    </material>

    <material name="black">
        <color rgba="0 0 0 1" />
    </material>

    <material name="red">
        <color rgba="1 0 0 1" />
    </material>

    <!--BASE
    FOOTPRINT-->
    <link name="base_footprint">
    </link>

    <!--BASE
    LINK-->
    <joint name="base_joint" type="fixed">
        <parent link="base_footprint" />
        <child link="base_link" />
        <origin xyz="0 0 0.0625" />
    </joint>

    <link name="base_link">
        <visual>
            <origin xyz="0 0.0 0.06" /><!-- 0.12/2 -->
            <geometry>
                <box size="0.25 0.18 0.12" />
            </geometry>
            <material name="white" />
        </visual>
        <collision>
            <origin xyz="0 0.0 0.06" /><!-- 0.12/2-->
            <geometry>
                <box size="0 0.18 0.12" />
            </geometry>
            <!-- <material name="black" /> -->
        </collision>
        <xacro:inertial_box mass="0.5" x="0.3" y="0.3" z="0.15">
            <origin xyz="0 0.0 0.06" rpy="0 0 0" />
        </xacro:inertial_box>
    </link>

    <gazebo reference="base_link">
        <material>Gazebo/Purple</material>
    </gazebo>

    <!--LEFT
    WHEEL BACK LINK-->
    <joint name="left_wheel_back_joint" type="continuous">
        <parent link="base_link" />
        <child link="left_wheel_back_link" />
        <origin
            xyz="-0.075 0.116 0.0" rpy="-${pi/2} 0.0 0.0" /><!-- 116 = 90+52/2-->
        <axis xyz="0.0 0.0 1" />
    </joint>

    <link name="left_wheel_back_link">
        <visual>
            <geometry>
                <cylinder radius="0.0625" length="0.05132" />
            </geometry>
            <material name="blue" />
        </visual>
        <collision>
            <geometry>
                <!-- <cylinder radius="0.0625" length="0.05132" /> -->
                <sphere radius="0.0625" />
            </geometry>
            <!-- <material name="orange" /> -->
        </collision>
        <xacro:inertial_cylinder mass="0.1" length="0.04" radius="0.05">
            <origin xyz="0 0 0" rpy="0 0 0" />
        </xacro:inertial_cylinder>
    </link>

    <gazebo reference="left_wheel_back_link">
        <material>Gazebo/Blue</material>
    </gazebo>

    <!--RIGHT
    WHEEL BACK LINK-->
    <joint name="right_wheel_back_joint" type="continuous">
        <parent link="base_link" />
        <child link="right_wheel_back_link" />
        <origin xyz="-0.075 -0.116 0.0" rpy="${pi/2} 0.0 0.0" /><!-- 116 = 90+52/2-->
        <axis xyz="0.0 0.0 -1" />
    </joint>

    <link name="right_wheel_back_link">
        <visual>
            <geometry>
                <cylinder radius="0.0625" length="0.05132" />
            </geometry>
            <material name="blue" />
        </visual>
        <collision>
            <geometry>
                <!-- <cylinder radius="0.0625" length="0.05132" /> -->
                <sphere radius="0.0625" />

            </geometry>
            <!-- <material name="orange" /> -->
        </collision>
        <xacro:inertial_cylinder mass="0.1" length="0.04" radius="0.05">
            <origin xyz="0 0 0" rpy="0 0 0" />
        </xacro:inertial_cylinder>
    </link>

    <gazebo reference="right_wheel_back_link">
        <material>Gazebo/Blue</material>

    </gazebo>

    <!-- CASTER WHEEL LINK -->

    <joint name="caster_wheel_joint" type="fixed">
        <parent link="base_link" />
        <child link="caster_wheel_link" />
        <origin xyz="0.06 0 0.0" />
    </joint>


    <link name="caster_wheel_link">
        <visual>
            <geometry>
                <sphere radius="0.0625" />
            </geometry>
            <material name="black" />
        </visual>
        <collision>
            <geometry>
                <sphere radius="0.0625" />
            </geometry>
        </collision>
        <xacro:inertial_sphere mass="0.1" radius="0.0625">
            <origin xyz="0 0 0" rpy="0 0 0" />
        </xacro:inertial_sphere>
    </link>

    <gazebo reference="caster_wheel_link">
        <material>Gazebo/Black</material>
        <mu1 value="0.002" />
        <mu2 value="0.002" />
    </gazebo>


</robot>